<?xml version="1.0" ?>
<!-- =================================================================================== -->
<!-- |    This document was autogenerated by xacro from bicopter_description/urdf/bicopter_assembly.xacro | -->
<!-- |    EDITING THIS FILE BY HAND IS NOT RECOMMENDED                                 | -->
<!-- =================================================================================== -->
<robot name="bicopter">
  <material name="blue">
    <color rgba="0 0 0.8 1"/>
  </material>
  <!-- MACRO PARA CRIACAO DO DEFAULT INERTIAL -->
  <!-- MACRO PARA CRIACAO DO TUBE ARM -->
  <!-- MACRO PARA CRIACAO DO ARM -->
  <!-- MACRO PARA CRIACAO DO ARM2 -->
  <!-- MACRO PARA CRIACAO DO LEG -->
  <!-- MACRO PARA CRIACAO DO TILT E SUAS TRANSMISSOES-->
  <!-- MACRO PARA CRIACAO DO ESTATOR -->
  <!--XACRO DO IMU : joint , link , sensor 
  
  <xacro:macro name="imu_sensor" params="xyz rpy parent">
     
    <link name="imu_sensor_link">
        <collision>
            <origin xyz="0 0 0" rpy="0 0 0"/>
            <geometry>
                <box size="0.02 0.02 0.01"/>
            </geometry>
        </collision>
        <visual>
            <geometry>
                <box size="0.02 0.02 0.01"/>
            </geometry>
            <origin xyz="0 0 0" rpy="0 0 0"/>
             <material name="blue"/>
        </visual>
        <inertial>
            <mass value="0.001" />
            <origin xyz="0 0 0" rpy="0 0 0"/>
            <inertia ixx="0.00000015" ixy="0" ixz="0" iyy="0.00000015" iyz="0" izz="0.00000015" />
        </inertial>
    </link>
    
    <joint name="imu_sensor_joint" type="fixed">
        <axis xyz="0 0 1" />
        <origin xyz="${xyz}" rpy="${rpy}"/>
        <parent link="${parent}"/>
        <child link="imu_sensor_link"/>
    </joint>
    
    <gazebo>
        <plugin name='imu_plugin' filename='libgazebo_ros_imu.so'>
              <always_on>1</always_on>
              <topicName>imu_data</topicName>
              <bodyName>imu_sensor_link</bodyName>
              <updateRateHZ>10.0</updateRateHZ>
              <gaussianNoise>0.0</gaussianNoise>
              <xyzOffset>0 0 0</xyzOffset>
              <rpyOffset>0 0 0</rpyOffset>
        </plugin>
    </gazebo>

  </xacro:macro>
  
   -->
  <!-- CRIACAO DOS IMU  
  
   <xacro:imu_sensor xyz="0 0.05 0" rpy="0 0 0" parent="base_link" />
   -->
  <!--MACRO PARA CRIACAO DO ROTOR -->
  <link name="base_link">
  </link>
  <link name="base_link_inertial">
    <visual>
      <origin rpy="0 0 0" xyz="0 0 0"/>
      <geometry>
        <mesh filename="package://bicopter_sim/bicopter_description/meshes/middle.dae"/>
      </geometry>
    </visual>
    <collision>
      <origin rpy="0 0 0" xyz="0 0 0"/>
      <geometry>
        <box size="0.178 0.17 0.015"/>
      </geometry>
    </collision>
    <inertial>
      <mass value="0.1419"/>
      <inertia ixx="1.942e-07" ixy="0" ixz="0" iyy="3.362e-07" iyz="-2.1e-09" izz="5.259e-07"/>
    </inertial>
  </link>
  <joint name="base_joint" type="fixed">
    <parent link="base_link"/>
    <child link="base_link_inertial"/>
  </joint>
  <!-- attach multirotor_base_plugin to the base_link -->
  <gazebo>
    <plugin filename="librotors_gazebo_multirotor_base_plugin.so" name="rosbag">
      <linkName>base_link</linkName>
      <rotorVelocitySlowdownSim>10</rotorVelocitySlowdownSim>
    </plugin>
  </gazebo>
  <!-- CRIACAO DOS MANCAIS E SUAS JUNTAS (JOINTS) -->
  <link name="right_mancal">
    <visual>
      <geometry>
        <mesh filename="package://bicopter_sim/bicopter_description/meshes/mancal_up.dae"/>
      </geometry>
      <origin rpy="0 0 1.57075" xyz="0 0 0"/>
    </visual>
    <collision>
      <geometry>
        <box size="0.04 0.05 0.02"/>
      </geometry>
      <origin rpy="0 0 0" xyz="0 0 0.010"/>
    </collision>
    <inertial>
      <mass value="0.01971"/>
      <inertia ixx="3.0541067e-09" ixy="-1.22135e-11" ixz="2.8446e-12" iyy="3.361632324e-07" iyz="-2.06933e-09" izz="5.258915527e-07"/>
    </inertial>
  </link>
  <joint name="base_to_right_mancal" type="fixed">
    <parent link="base_link"/>
    <child link="right_mancal"/>
    <origin xyz="-0.07 0 0.0142"/>
  </joint>
  <link name="left_mancal">
    <visual>
      <geometry>
        <mesh filename="package://bicopter_sim/bicopter_description/meshes/mancal_up.dae"/>
      </geometry>
      <origin rpy="0 0 1.57075" xyz="0 0 0"/>
    </visual>
    <collision>
      <geometry>
        <box size="0.04 0.05 0.02"/>
      </geometry>
      <origin rpy="0 0 0" xyz="0 0 0.010"/>
    </collision>
    <inertial>
      <mass value="0.01971"/>
      <inertia ixx="3.0541067e-09" ixy="-1.22135e-11" ixz="2.8446e-12" iyy="3.361632324e-07" iyz="-2.06933e-09" izz="5.258915527e-07"/>
    </inertial>
  </link>
  <joint name="base_to_left_mancal" type="fixed">
    <parent link="base_link"/>
    <child link="left_mancal"/>
    <origin xyz="0.07 0 0.0142"/>
  </joint>
  <!-- CRIACAO DOS TUBE ARM E SUAS JUNTAS (JOINTS) -->
  <link name="right_tube_arm">
    <visual>
      <geometry>
        <mesh filename="package://bicopter_sim/bicopter_description/meshes/tube_arm.dae"/>
      </geometry>
      <origin rpy="0 0 0" xyz="0 0 0"/>
    </visual>
    <collision>
      <geometry>
        <cylinder length="0.12" radius="0.01"/>
      </geometry>
      <origin rpy="0 1.57075 0" xyz="0 0 0"/>
    </collision>
    <inertial>
      <mass value="0.03022"/>
      <inertia ixx="1.7960983e-09" ixy="-2.3981262e-09" ixz="-2.08e-14" iyy="2.15995621e-08" iyz="-7e-16" izz="2.17520676e-08"/>
    </inertial>
  </link>
  <joint name="base_to_right_tube_arm" type="fixed">
    <parent link="base_link"/>
    <child link="right_tube_arm"/>
    <origin xyz="-0.115 0 0.0142"/>
  </joint>
  <link name="left_tube_arm">
    <visual>
      <geometry>
        <mesh filename="package://bicopter_sim/bicopter_description/meshes/tube_arm.dae"/>
      </geometry>
      <origin rpy="0 0 0" xyz="0 0 0"/>
    </visual>
    <collision>
      <geometry>
        <cylinder length="0.12" radius="0.01"/>
      </geometry>
      <origin rpy="0 1.57075 0" xyz="0 0 0"/>
    </collision>
    <inertial>
      <mass value="0.03022"/>
      <inertia ixx="1.7960983e-09" ixy="-2.3981262e-09" ixz="-2.08e-14" iyy="2.15995621e-08" iyz="-7e-16" izz="2.17520676e-08"/>
    </inertial>
  </link>
  <joint name="base_to_left_tube_arm" type="fixed">
    <parent link="base_link"/>
    <child link="left_tube_arm"/>
    <origin xyz="0.115 0 0.0142"/>
  </joint>
  <!-- CRIACAO DOS ARM E SUAS JUNTAS (JOINTS) -->
  <link name="right_arm">
    <visual>
      <geometry>
        <mesh filename="package://bicopter_sim/bicopter_description/meshes/arm_max.dae"/>
      </geometry>
      <origin rpy="0.0 0.0 0" xyz="0 0 0"/>
    </visual>
    <collision>
      <geometry>
        <box size="0.12 0.006 0.038"/>
      </geometry>
      <origin rpy="0 0 0" xyz="0.04 0.005 -0.005"/>
    </collision>
    <inertial>
      <mass value="0.03133"/>
      <inertia ixx="4.021067e-09" ixy="2.7460985e-09" ixz="-1.840184e-10" iyy="3.54965027e-08" iyz="-7.66613e-11" izz="3.39598694e-08"/>
    </inertial>
  </link>
  <joint name="base_to_right_arm" type="fixed">
    <parent link="right_tube_arm"/>
    <child link="right_arm"/>
    <origin xyz="-0.1 0.022 0"/>
  </joint>
  <link name="left_arm">
    <visual>
      <geometry>
        <mesh filename="package://bicopter_sim/bicopter_description/meshes/arm_max.dae"/>
      </geometry>
      <origin rpy="3.1415 3.1415 0" xyz="0 0 0"/>
    </visual>
    <collision>
      <geometry>
        <box size="0.12 0.006 0.038"/>
      </geometry>
      <origin rpy="0 0 0" xyz="-0.04 -0.005 -0.005"/>
    </collision>
    <inertial>
      <mass value="0.03133"/>
      <inertia ixx="4.021067e-09" ixy="2.7460985e-09" ixz="-1.840184e-10" iyy="3.54965027e-08" iyz="-7.66613e-11" izz="3.39598694e-08"/>
    </inertial>
  </link>
  <joint name="base_to_left_arm" type="fixed">
    <parent link="left_tube_arm"/>
    <child link="left_arm"/>
    <origin xyz="0.1 -0.022 0"/>
  </joint>
  <!-- CRIACAO DOS ARM2 E SUAS JUNTAS (JOINTS) -->
  <link name="right_arm2">
    <visual>
      <geometry>
        <mesh filename="package://bicopter_sim/bicopter_description/meshes/arm_min.dae"/>
      </geometry>
      <origin rpy="0.0 0.0 0" xyz="0 0 0"/>
    </visual>
    <collision>
      <geometry>
        <box size="0.11 0.007 0.035"/>
      </geometry>
      <origin rpy="0 0 0" xyz="0.045 0.005 -0.001"/>
    </collision>
    <inertial>
      <mass value="0.01847"/>
      <inertia ixx="3.201813e-10" ixy="0.0" ixz="0.0" iyy="5.4531342e-09" iyz="0.0" izz="5.4531342e-09"/>
    </inertial>
  </link>
  <joint name="base_to_right_arm2" type="fixed">
    <parent link="right_tube_arm"/>
    <child link="right_arm2"/>
    <origin xyz="-0.1 -0.03 0"/>
  </joint>
  <link name="left_arm2">
    <visual>
      <geometry>
        <mesh filename="package://bicopter_sim/bicopter_description/meshes/arm_min.dae"/>
      </geometry>
      <origin rpy="3.1415 3.1415 0" xyz="0 0 0"/>
    </visual>
    <collision>
      <geometry>
        <box size="0.11 0.007 0.035"/>
      </geometry>
      <origin rpy="0 0 0" xyz="-0.045 -0.005 -0.001"/>
    </collision>
    <inertial>
      <mass value="0.01847"/>
      <inertia ixx="3.201813e-10" ixy="0.0" ixz="0.0" iyy="5.4531342e-09" iyz="0.0" izz="5.4531342e-09"/>
    </inertial>
  </link>
  <joint name="base_to_left_arm2" type="fixed">
    <parent link="left_tube_arm"/>
    <child link="left_arm2"/>
    <origin xyz="0.1 0.03 0"/>
  </joint>
  <!-- CRIACAO DOS LEG E SUAS JUNTAS (JOINTS) -->
  <link name="right_leg">
    <visual>
      <geometry>
        <mesh filename="package://bicopter_sim/bicopter_description/meshes/land_leg.dae"/>
      </geometry>
      <origin rpy="0 0 0" xyz="0 0 0"/>
    </visual>
    <collision>
      <geometry>
        <box size="0.007 0.155 0.07"/>
      </geometry>
      <origin rpy="0 0 0" xyz="0 0 -0.035"/>
    </collision>
    <inertial>
      <mass value="0.00823"/>
      <inertia ixx="1.91376434e-08" ixy="7e-16" ixz="-2e-16" iyy="4.2566975e-09" iyz="-1e-15" izz="1.49469467e-08"/>
    </inertial>
  </link>
  <joint name="base_to_right_leg" type="fixed">
    <parent link="base_link"/>
    <child link="right_leg"/>
    <origin xyz="-0.035 0.0075 -0.0025"/>
  </joint>
  <gazebo reference="right_leg">
    <mu1 value="200.0"/>
    <mu2 value="100.0"/>
    <kp value="10000000.0"/>
    <kd value="1.0"/>
  </gazebo>
  <link name="left_leg">
    <visual>
      <geometry>
        <mesh filename="package://bicopter_sim/bicopter_description/meshes/land_leg.dae"/>
      </geometry>
      <origin rpy="0 0 0" xyz="0 0 0"/>
    </visual>
    <collision>
      <geometry>
        <box size="0.007 0.155 0.07"/>
      </geometry>
      <origin rpy="0 0 0" xyz="0 0 -0.035"/>
    </collision>
    <inertial>
      <mass value="0.00823"/>
      <inertia ixx="1.91376434e-08" ixy="7e-16" ixz="-2e-16" iyy="4.2566975e-09" iyz="-1e-15" izz="1.49469467e-08"/>
    </inertial>
  </link>
  <joint name="base_to_left_leg" type="fixed">
    <parent link="base_link"/>
    <child link="left_leg"/>
    <origin xyz="0.035 0.0075 -0.0025"/>
  </joint>
  <gazebo reference="left_leg">
    <mu1 value="200.0"/>
    <mu2 value="100.0"/>
    <kp value="10000000.0"/>
    <kd value="1.0"/>
  </gazebo>
  <!-- CRIACAO DOS TILT E SUAS JUNTAS (JOINTS) -->
  <link name="right_tilt">
    <visual>
      <geometry>
        <mesh filename="package://bicopter_sim/bicopter_description/meshes/motor_base.dae"/>
      </geometry>
      <origin rpy="0 0 0" xyz="0 0 0"/>
    </visual>
    <collision>
      <geometry>
        <cylinder length="0.005" radius="0.02"/>
      </geometry>
      <origin rpy="0 0 0" xyz="0 0 -0.01"/>
    </collision>
    <inertial>
      <mass value="0.00526"/>
      <inertia ixx="1.8322357e-09" ixy="2.628e-13" ixz="4.879e-13" iyy="3.454043e-10" iyz="-2.90679e-11" izz="1.9750971e-09"/>
    </inertial>
  </link>
  <joint name="arm_to_right_tilt" type="revolute">
    <axis xyz="0 -1 0"/>
    <limit effort="1000.0" lower="0.0" upper="1.57075" velocity="0.5"/>
    <origin rpy="0 0 0" xyz="0 -0.02 0"/>
    <parent link="right_arm"/>
    <child link="right_tilt"/>
    <origin xyz="-0.035 -0.0075 -0.0025"/>
  </joint>
  <!--
    <joint name="arm_to_${prefix}_tilt" type="fixed">
      <origin rpy="0 0 0" xyz="0 ${reflect*0.02} 0"/>
      <parent link="${prefix}_arm"/>
      <child link="${prefix}_tilt"/>
      <origin xyz="${reflect*0.035} ${reflect*0.0075} -0.0025"/>
    </joint>
    -->
  <!-- This block connects the tilt_rotor joint to an actuator (motor), which informs both
  simulation and visualization of the robot -->
  <transmission name="right_tilt_trans" type="SimpleTransmission">
    <type>transmission_interface/SimpleTransmission</type>
    <actuator name="right_tilt_motor">
      <mechanicalReduction>1</mechanicalReduction>
    </actuator>
    <joint name="arm_to_right_tilt">
      <hardwareInterface>hardware_interface/PositionJointInterface</hardwareInterface>
    </joint>
  </transmission>
  <link name="left_tilt">
    <visual>
      <geometry>
        <mesh filename="package://bicopter_sim/bicopter_description/meshes/motor_base.dae"/>
      </geometry>
      <origin rpy="0 0 0" xyz="0 0 0"/>
    </visual>
    <collision>
      <geometry>
        <cylinder length="0.005" radius="0.02"/>
      </geometry>
      <origin rpy="0 0 0" xyz="0 0 -0.01"/>
    </collision>
    <inertial>
      <mass value="0.00526"/>
      <inertia ixx="1.8322357e-09" ixy="2.628e-13" ixz="4.879e-13" iyy="3.454043e-10" iyz="-2.90679e-11" izz="1.9750971e-09"/>
    </inertial>
  </link>
  <joint name="arm_to_left_tilt" type="revolute">
    <axis xyz="0 1 0"/>
    <limit effort="1000.0" lower="0.0" upper="1.57075" velocity="0.5"/>
    <origin rpy="0 0 0" xyz="0 0.02 0"/>
    <parent link="left_arm"/>
    <child link="left_tilt"/>
    <origin xyz="0.035 0.0075 -0.0025"/>
  </joint>
  <!--
    <joint name="arm_to_${prefix}_tilt" type="fixed">
      <origin rpy="0 0 0" xyz="0 ${reflect*0.02} 0"/>
      <parent link="${prefix}_arm"/>
      <child link="${prefix}_tilt"/>
      <origin xyz="${reflect*0.035} ${reflect*0.0075} -0.0025"/>
    </joint>
    -->
  <!-- This block connects the tilt_rotor joint to an actuator (motor), which informs both
  simulation and visualization of the robot -->
  <transmission name="left_tilt_trans" type="SimpleTransmission">
    <type>transmission_interface/SimpleTransmission</type>
    <actuator name="left_tilt_motor">
      <mechanicalReduction>1</mechanicalReduction>
    </actuator>
    <joint name="arm_to_left_tilt">
      <hardwareInterface>hardware_interface/PositionJointInterface</hardwareInterface>
    </joint>
  </transmission>
  <!-- CRIACAO DOS STATOR E SUAS JUNTAS (JOINTS) -->
  <link name="right_0_stator">
    <visual>
      <geometry>
        <cylinder length="0.035" radius="0.014"/>
      </geometry>
      <origin rpy="0 0 0" xyz="0 0 0.009"/>
    </visual>
    <collision>
      <geometry>
        <cylinder length="0.035" radius="0.014"/>
      </geometry>
      <origin rpy="0 0 0" xyz="0 0 0.011"/>
    </collision>
    <inertial>
      <mass value="0.053"/>
      <inertia ixx="8.007416666666667e-06" ixy="0.0" ixz="0.0" iyy="8.007416666666667e-06" iyz="0.0" izz="5.194000000000001e-06"/>
    </inertial>
  </link>
  <joint name="tilt_to_right_0_stator" type="revolute">
    <axis xyz="0 -1 0"/>
    <limit effort="1000.0" lower="0.0" upper="0.001" velocity="0.5"/>
    <parent link="right_tilt"/>
    <child link="right_0_stator"/>
    <origin xyz="0 0 0"/>
  </joint>
  <transmission name="right_estator_trans" type="SimpleTransmission">
    <type>transmission_interface/SimpleTransmission</type>
    <actuator name="right_estator_motor">
      <mechanicalReduction>1</mechanicalReduction>
    </actuator>
    <joint name="tilt_to_right_estator">
      <hardwareInterface>hardware_interface/PositionJointInterface</hardwareInterface>
    </joint>
  </transmission>
  <!--
    <joint name="tilt_to_${prefix}_${number}_stator" type="fixed">
      <parent link="${parent}"/>
      <child link="${prefix}_${number}_stator"/>
      <origin xyz="0 0 0.0${number}"/>
    </joint>
    -->
  <gazebo reference="right_0_stator">
    <material>Gazebo/DarkGrey</material>
  </gazebo>
  <link name="left_0_stator">
    <visual>
      <geometry>
        <cylinder length="0.035" radius="0.014"/>
      </geometry>
      <origin rpy="0 0 0" xyz="0 0 0.009"/>
    </visual>
    <collision>
      <geometry>
        <cylinder length="0.035" radius="0.014"/>
      </geometry>
      <origin rpy="0 0 0" xyz="0 0 0.011"/>
    </collision>
    <inertial>
      <mass value="0.053"/>
      <inertia ixx="8.007416666666667e-06" ixy="0.0" ixz="0.0" iyy="8.007416666666667e-06" iyz="0.0" izz="5.194000000000001e-06"/>
    </inertial>
  </link>
  <joint name="tilt_to_left_0_stator" type="revolute">
    <axis xyz="0 1 0"/>
    <limit effort="1000.0" lower="0.0" upper="0.001" velocity="0.5"/>
    <parent link="left_tilt"/>
    <child link="left_0_stator"/>
    <origin xyz="0 0 0"/>
  </joint>
  <transmission name="left_estator_trans" type="SimpleTransmission">
    <type>transmission_interface/SimpleTransmission</type>
    <actuator name="left_estator_motor">
      <mechanicalReduction>1</mechanicalReduction>
    </actuator>
    <joint name="tilt_to_left_estator">
      <hardwareInterface>hardware_interface/PositionJointInterface</hardwareInterface>
    </joint>
  </transmission>
  <!--
    <joint name="tilt_to_${prefix}_${number}_stator" type="fixed">
      <parent link="${parent}"/>
      <child link="${prefix}_${number}_stator"/>
      <origin xyz="0 0 0.0${number}"/>
    </joint>
    -->
  <gazebo reference="left_0_stator">
    <material>Gazebo/DarkGrey</material>
  </gazebo>
  <!--
    <joint name="rotor_${motor_number}_joint" type="fixed">
      <xacro:insert_block name="origin" />
      <parent link="${parent}" />
      <child link="rotor_${motor_number}" />
    </joint>
    -->
  <!-- TODO(ff): not currently set because it's not yet supported -->
  <!-- <gazebo reference="rotor_${motor_number}_joint"> <axis> <xyz>0 0 1</xyz>
      <limit> <velocity> ${max_rot_velocity} </velocity> </limit> </axis> </gazebo> -->
  <link name="right_rotor">
    <inertial>
      <mass value="0.005"/>
      <!-- [kg] -->
      <inertia ixx="9.75e-07" ixy="0.0" ixz="0.0" iyy="0.00032670416666666667" iyz="0.0" izz="0.0003276041666666667"/>
    </inertial>
    <visual>
      <geometry>
        <mesh filename="package://bicopter_sim/bicopter_description/meshes/propeller_ccw.dae" scale=".12 .12 .12"/>
      </geometry>
    </visual>
    <collision>
      <geometry>
        <cylinder length="0.005" radius="0.14"/>
        <!-- [m] -->
      </geometry>
    </collision>
  </link>
  <!-- Rotor joint and link  -->
  <joint name="right_rotor_joint" type="continuous">
    <origin rpy="0 0 0" xyz="0 0 0.033"/>
    <axis xyz="0 0 1"/>
    <limit effort="1000" velocity="1.0"/>
    <parent link="right_0_stator"/>
    <child link="right_rotor"/>
  </joint>
  <transmission name="right_motor_trans" type="SimpleTransmission">
    <type>transmission_interface/SimpleTransmission</type>
    <actuator name="right_motor">
      <mechanicalReduction>1</mechanicalReduction>
    </actuator>
    <joint name="right_rotor_joint">
      <hardwareInterface>hardware_interface/PositionJointInterface</hardwareInterface>
    </joint>
  </transmission>
  <gazebo>
    <plugin filename="librotors_gazebo_motor_model.so" name="right_motor_model">
      <jointName>right_rotor_joint</jointName>
      <linkName>right_rotor</linkName>
      <turningDirection>ccw</turningDirection>
      <timeConstantUp>0.15</timeConstantUp>
      <timeConstantDown>0.15</timeConstantDown>
      <maxRotVelocity>770</maxRotVelocity>
      <motorConstant>2.39e-05</motorConstant>
      <momentConstant>0.016</momentConstant>
      <commandSubTopic>gazebo/command/motor_speed</commandSubTopic>
      <motorNumber>0</motorNumber>
      <rotorDragCoefficient>1.3858e-06</rotorDragCoefficient>
      <rollingMomentCoefficient>1e-06</rollingMomentCoefficient>
      <motorSpeedPubTopic>motor_speed/right</motorSpeedPubTopic>
      <rotorVelocitySlowdownSim>10</rotorVelocitySlowdownSim>
    </plugin>
  </gazebo>
  <gazebo reference="right_rotor">
    <material>Gazebo/Blue</material>
  </gazebo>
  <!--
    <joint name="rotor_${motor_number}_joint" type="fixed">
      <xacro:insert_block name="origin" />
      <parent link="${parent}" />
      <child link="rotor_${motor_number}" />
    </joint>
    -->
  <!-- TODO(ff): not currently set because it's not yet supported -->
  <!-- <gazebo reference="rotor_${motor_number}_joint"> <axis> <xyz>0 0 1</xyz>
      <limit> <velocity> ${max_rot_velocity} </velocity> </limit> </axis> </gazebo> -->
  <link name="left_rotor">
    <inertial>
      <mass value="0.005"/>
      <!-- [kg] -->
      <inertia ixx="9.75e-07" ixy="0.0" ixz="0.0" iyy="0.00032670416666666667" iyz="0.0" izz="0.0003276041666666667"/>
    </inertial>
    <visual>
      <geometry>
        <mesh filename="package://bicopter_sim/bicopter_description/meshes/propeller_cw.dae" scale=".12 .12 .12"/>
      </geometry>
    </visual>
    <collision>
      <geometry>
        <cylinder length="0.005" radius="0.14"/>
        <!-- [m] -->
      </geometry>
    </collision>
  </link>
  <!-- Rotor joint and link  -->
  <joint name="left_rotor_joint" type="continuous">
    <origin rpy="0 0 0" xyz="0 0 0.033"/>
    <axis xyz="0 0 1"/>
    <limit effort="1000" velocity="1.0"/>
    <parent link="left_0_stator"/>
    <child link="left_rotor"/>
  </joint>
  <transmission name="left_motor_trans" type="SimpleTransmission">
    <type>transmission_interface/SimpleTransmission</type>
    <actuator name="left_motor">
      <mechanicalReduction>1</mechanicalReduction>
    </actuator>
    <joint name="left_rotor_joint">
      <hardwareInterface>hardware_interface/PositionJointInterface</hardwareInterface>
    </joint>
  </transmission>
  <gazebo>
    <plugin filename="librotors_gazebo_motor_model.so" name="left_motor_model">
      <jointName>left_rotor_joint</jointName>
      <linkName>left_rotor</linkName>
      <turningDirection>cw</turningDirection>
      <timeConstantUp>0.15</timeConstantUp>
      <timeConstantDown>0.15</timeConstantDown>
      <maxRotVelocity>770</maxRotVelocity>
      <motorConstant>2.39e-05</motorConstant>
      <momentConstant>0.016</momentConstant>
      <commandSubTopic>gazebo/command/motor_speed</commandSubTopic>
      <motorNumber>0</motorNumber>
      <rotorDragCoefficient>1.3858e-06</rotorDragCoefficient>
      <rollingMomentCoefficient>1e-06</rollingMomentCoefficient>
      <motorSpeedPubTopic>motor_speed/left</motorSpeedPubTopic>
      <rotorVelocitySlowdownSim>10</rotorVelocitySlowdownSim>
    </plugin>
  </gazebo>
  <gazebo reference="left_rotor">
    <material>Gazebo/Blue</material>
  </gazebo>
  <!-- CONECTANDO ROS TO GAZEBO -->
  <gazebo>
    <plugin filename="libgazebo_ros_control.so" name="gazebo_ros_control">
	   </plugin>
  </gazebo>
</robot>
