<?xml version="1.0"?>
<robot xmlns:xacro="http://ros.org/wiki/xacro">
  
  <xacro:property name="pi" value="3.1415" />
   <material name="blue">
    <color rgba="0 0 0.8 1"/>
  </material>

  <!-- MACRO PARA CRIACAO DO DEFAULT INERTIAL -->
    
  <xacro:macro name="default_inertial" params="mass ixx ixy ixz iyy iyz izz">
    <inertial>
      <mass value="${mass}" />
      <inertia ixx="${ixx}" ixy="${ixy}" ixz="${ixz}" iyy="${iyy}" iyz="${iyz}" izz="${izz}" />
    </inertial>
  </xacro:macro>

  <!-- MACRO PARA CRIACAO DA BASE DO BICOPTER -->
  <xacro:macro name="bicopter_base">
  <!---->
  <link name="base_link">
  </link>
  
  <joint name="base_joint" type="fixed">
    <parent link="base_link"/>
    <child link="base_link_inertial"/>
  </joint>
  
  
  <link name="base_link_inertial">  
  
    <visual>
      <origin rpy="0 0 0" xyz="0 0 0"/>
      <geometry>
        <mesh filename="package://bicopter_sim/bicopter_description/meshes/middle.dae"/>
      </geometry>
    </visual>
    
    <collision>
      <origin rpy="0 0 0" xyz="0 0 0"/>
      <geometry>
        <box size="0.178 0.17 0.015"/>
      </geometry>
    </collision>
    
    <xacro:default_inertial mass="0.1419" ixx="0.1942e-6" ixy="0" ixz="0" iyy="0.3362e-6" iyz="-0.0021e-6" izz="0.5259e-6"/>    
  
  </link>
  
  <!-- attach multirotor_base_plugin to the base_link -->
  <gazebo>
    <plugin filename="librotors_gazebo_multirotor_base_plugin.so" name="rosbag">
      <linkName>base_link</linkName>
      <rotorVelocitySlowdownSim>${rotor_velocity_slowdown_sim}</rotorVelocitySlowdownSim>
    </plugin>
  </gazebo>
  
  </xacro:macro>

  
  <!-- MACRO PARA CRIACAO DO MANCAL -->
  <xacro:macro name="mancal" params="prefix reflect">
    <link name="${prefix}_mancal">
      <visual>
        <geometry>
         <mesh filename="package://bicopter_sim/bicopter_description/meshes/mancal_up.dae"/>
        </geometry>
        <origin rpy="0 0 ${pi/2}" xyz="0 0 0"/>
      </visual>
      <collision>
        <geometry>
          <box size="0.04 0.05 0.02"/>
        </geometry>
        <origin rpy="0 0 0" xyz="0 0 0.010"/>
      </collision>
      <xacro:default_inertial mass="0.01971" ixx="3.0541067e-09" ixy="-1.22135e-11" ixz="2.8446e-12" iyy="3.361632324e-07" iyz="-2.06933e-09" izz="5.258915527e-07"/>
    </link>

    <joint name="base_to_${prefix}_mancal" type="fixed">
      <parent link="base_link"/>
      <child link="${prefix}_mancal"/>
      <origin xyz="${reflect*0.07} 0 0.0142" />
    </joint>
  </xacro:macro>
  
  <!-- MACRO PARA CRIACAO DO TUBE ARM -->
  
  <xacro:macro name="tube_arm" params="prefix reflect">
    <link name="${prefix}_tube_arm">
      <visual>
        <geometry>
         <mesh filename="package://bicopter_sim/bicopter_description/meshes/tube_arm.dae"/>
        </geometry>
        <origin rpy="0 0 0" xyz="0 0 0"/>
      </visual>
      <collision>
      <geometry>
        <cylinder length="0.12" radius="0.01"/>
      </geometry>
       <origin rpy="0 ${pi/2} 0" xyz="0 0 0"/>
    </collision>
      <xacro:default_inertial mass="0.03022" ixx="1.7960983e-09" ixy="-2.3981262e-09" ixz="-2.08e-14" iyy="2.15995621e-08" iyz="-7.0e-16" izz="2.17520676e-08"/>
    </link>

    <joint name="base_to_${prefix}_tube_arm" type="fixed">
      <parent link="base_link"/>
      <child link="${prefix}_tube_arm"/>
      <origin xyz="${reflect*0.115} 0 0.0142" />
    </joint>
  </xacro:macro>
  
  <!-- MACRO PARA CRIACAO DO ARM -->
  
   <xacro:macro name="arm" params="prefix releve reflect">
    
    <link name="${prefix}_arm">
      <visual>
        <geometry>
         <mesh filename="package://bicopter_sim/bicopter_description/meshes/arm_max.dae"/>
        </geometry>
        <origin rpy="${releve*pi} ${releve*pi} 0" xyz="0 0 0"/>
      </visual>
      <collision>
        <geometry>
          <box size="0.12 0.006 0.038"/>
        </geometry>
        <origin rpy="0 0 0" xyz="${reflect*-0.04} ${reflect*-0.005} -0.005"/>
      </collision>
      <xacro:default_inertial mass="0.03133" ixx="4.021067e-09" ixy="2.7460985e-09" ixz="-1.840184e-10" iyy="3.54965027e-08" iyz="-7.66613e-11" izz="3.39598694e-08"/>
    </link>

    <joint name="base_to_${prefix}_arm" type="fixed">
      <parent link="${prefix}_tube_arm"/>
      <child link="${prefix}_arm"/>
      <origin xyz="${reflect*0.1} ${reflect*-0.022} 0"/>
    </joint>
    
  </xacro:macro>
  
  <!-- MACRO PARA CRIACAO DO ARM2 -->
  
   <xacro:macro name="arm2" params="prefix releve reflect">
    
    <link name="${prefix}_arm2">
      <visual>
        <geometry>
         <mesh filename="package://bicopter_sim/bicopter_description/meshes/arm_min.dae"/>
        </geometry>
        <origin rpy="${releve*pi} ${releve*pi} 0" xyz="0 0 0"/>
      </visual>
      <collision>
        <geometry>
          <box size="0.11 0.007 0.035"/>
        </geometry>
        <origin rpy="0 0 0" xyz="${reflect*-0.045} ${reflect*-0.005} -0.001"/>
      </collision>
      <xacro:default_inertial mass="0.01847" ixx="3.201813e-10" ixy="0.00" ixz="0.00" iyy="5.4531342e-09" iyz="0.00" izz="5.4531342e-09"/>
    </link>

    <joint name="base_to_${prefix}_arm2" type="fixed">
      <parent link="${prefix}_tube_arm"/>
      <child link="${prefix}_arm2"/>
      <origin xyz="${reflect*0.1} ${reflect*0.03} 0"/>
    </joint>
    
  </xacro:macro>
  
   <!-- MACRO PARA CRIACAO DO LEG -->
  
   <xacro:macro name="leg" params="prefix reflect">
    
    <link name="${prefix}_leg">
      <visual>
        <geometry>
         <mesh filename="package://bicopter_sim/bicopter_description/meshes/land_leg.dae"/>
        </geometry>
        <origin rpy="0 0 0" xyz="0 0 0"/>
      </visual>
      <collision>
        <geometry>
         <box size="0.007 0.155 0.07"/>
        </geometry>
        <origin rpy="0 0 0" xyz="0 0 -0.035"/>
      </collision>
      <xacro:default_inertial mass="0.00823" ixx="1.91376434e-08" ixy="7.0e-16" ixz="-2.0e-16" iyy="4.2566975e-09" iyz="-1.0e-15" izz="1.49469467e-08"/>
    </link>

    <joint name="base_to_${prefix}_leg" type="fixed">
      <parent link="base_link"/>
      <child link="${prefix}_leg"/>
      <origin xyz="${reflect*0.035} 0.0075 -0.0025"/>
    </joint>
    <gazebo reference="${prefix}_leg">
      <mu1 value="200.0"/>
      <mu2 value="100.0"/>
      <kp value="10000000.0" />
      <kd value="1.0" />
    </gazebo>
  </xacro:macro>
  
   <!-- MACRO PARA CRIACAO DO TILT E SUAS TRANSMISSOES-->
  
   <xacro:macro name="tilt" params="prefix reflect">
    
    <link name="${prefix}_tilt">
      <visual>
        <geometry>
         <mesh filename="package://bicopter_sim/bicopter_description/meshes/motor_base.dae"/>
        </geometry>
        <origin rpy="0 0 0" xyz="0 0 0"/>
      </visual>
      <collision>
        <geometry>
          <cylinder length="0.005" radius="0.02"/>
        </geometry>
      <origin rpy="0 0 0" xyz="0 0 -0.01"/>
      </collision>
      <xacro:default_inertial mass="0.00526" ixx="1.8322357e-09" ixy="2.628e-13" ixz="4.879e-13" iyy="3.454043e-10" iyz="-2.906790e-11" izz="1.9750971e-09"/>
    </link>
    
    <joint name="arm_to_${prefix}_tilt" type="revolute">
      <axis xyz="0 ${reflect*1} 0"/>
      <limit effort="1000.0" lower="0.0" upper="${pi/2}" velocity="0.5"/>
      <origin rpy="0 0 0" xyz="0 ${reflect*0.02} 0"/>
      <parent link="${prefix}_arm"/>
      <child link="${prefix}_tilt"/>
      <origin xyz="${reflect*0.035} ${reflect*0.0075} -0.0025"/>
    </joint>
    
    <!--
    <joint name="arm_to_${prefix}_tilt" type="fixed">
      <origin rpy="0 0 0" xyz="0 ${reflect*0.02} 0"/>
      <parent link="${prefix}_arm"/>
      <child link="${prefix}_tilt"/>
      <origin xyz="${reflect*0.035} ${reflect*0.0075} -0.0025"/>
    </joint>
    -->
    
     <!-- This block connects the tilt_rotor joint to an actuator (motor), which informs both
  simulation and visualization of the robot -->
  
    <transmission name="${prefix}_tilt_trans" type="SimpleTransmission">
      <type>transmission_interface/SimpleTransmission</type>
      <actuator name="${prefix}_tilt_motor">
        <mechanicalReduction>1</mechanicalReduction>
      </actuator>
      <joint name="arm_to_${prefix}_tilt">
        <hardwareInterface>hardware_interface/PositionJointInterface</hardwareInterface>
      </joint>
    </transmission>
    
  </xacro:macro>
  
  <!-- MACRO PARA CRIACAO DO ESTATOR -->
  
   <xacro:macro name="stator" params="prefix reflect parent">
    
    <link name="${prefix}_stator">
      <visual>
        <geometry>
         <cylinder length="0.035" radius="0.014"/>
        </geometry>
        <origin rpy="0 0 0" xyz="0 0 0.009"/>
      </visual>
      <collision>
        <geometry>
         <cylinder length="0.035" radius="0.014"/>
        </geometry>
        <origin rpy="0 0 0" xyz="0 0 0.011"/>
      </collision>
      <xacro:default_inertial mass="0.053" ixx="${(1/12)*0.053*(3*0.014*0.014+0.035*0.035)}" ixy="0.00" ixz="0.00" iyy="${(1/12)*0.053*(3*0.014*0.014+0.035*0.035)}" iyz="0.00" izz="${(1/2)*0.053*(0.014*0.014)}"/>
    </link>
    
    <joint name="tilt_to_${prefix}_estator" type="fixed">
      <axis xyz="0 0 0"/>
      <limit effort="1000.0" lower="0.0" upper="0.00" velocity="0.5"/>
      <parent link="${parent}"/>
      <child link="${prefix}_stator"/>
    </joint>
    <!--
    <joint name="tilt_to_${prefix}_estator" type="revolute">
      <axis xyz="0 ${reflect*1} 0"/>
      <limit effort="1000.0" lower="0.0" upper="0.00" velocity="0.5"/>
      <parent link="${parent}"/>
      <child link="${prefix}_stator"/>
      <origin xyz="0 0 0"/>
    </joint>
    
    <transmission name="${prefix}_estator_trans" type="SimpleTransmission">
      <type>transmission_interface/SimpleTransmission</type>
      <actuator name="${prefix}_estator_motor">
        <mechanicalReduction>1</mechanicalReduction>
      </actuator>
      <joint name="tilt_to_${prefix}_estator">
        <hardwareInterface>hardware_interface/PositionJointInterface</hardwareInterface>
      </joint>
    </transmission>
    -->
    <gazebo reference="${prefix}_stator">
      <material>Gazebo/${color}</material>
    </gazebo>
    
  </xacro:macro>
  
  <!--MACRO PARA CRIACAO DO ROTOR -->
  
  <xacro:macro name="vertical_rotor" params="prefix direction motor_constant moment_constant parent mass_rotor radius_rotor time_constant_up time_constant_down max_rot_velocity motor_number rotor_drag_coefficient rolling_moment_coefficient color mesh mesh_scale *origin *inertia">
   
    <!--
    <joint name="rotor_${motor_number}_joint" type="fixed">
      <xacro:insert_block name="origin" />
      <parent link="${parent}" />
      <child link="rotor_${motor_number}" />
    </joint>
    -->
    
    <link name="${prefix}_rotor">
      <inertial>
        <mass value="${mass_rotor}" /> <!-- [kg] -->
        <xacro:insert_block name="inertia" />
      </inertial>
      <visual>
        <geometry>
          <mesh filename="package://bicopter_sim/bicopter_description/meshes/${mesh}_${direction}.dae" scale="${mesh_scale}" />
        </geometry>
      </visual>
      <collision>
        <geometry>
          <cylinder length="0.005" radius="${radius_rotor}" /> <!-- [m] -->
        </geometry>
      </collision>
    </link>
    
     <!-- Rotor joint and link  -->
    <joint name="${prefix}_rotor_joint" type="continuous">
      <xacro:insert_block name="origin" />
      <axis xyz="0 0 1" />
      <limit effort="1000" velocity="1.0"/>
      <parent link="${parent}" />
      <child link="${prefix}_rotor" />
    </joint>
    
    <transmission name="${prefix}_motor_trans" type="SimpleTransmission">
      <type>transmission_interface/SimpleTransmission</type>
      <actuator name="${prefix}_motor">
        <mechanicalReduction>1</mechanicalReduction>
      </actuator>
      <joint name="${prefix}_rotor_joint">
        <hardwareInterface>hardware_interface/PositionJointInterface</hardwareInterface>
      </joint>
    </transmission>
    
    <gazebo>
      <plugin name="${prefix}_motor_model" filename="librotors_gazebo_motor_model.so">
        <jointName>${prefix}_rotor_joint</jointName>
        <linkName>${prefix}_rotor</linkName>
        <turningDirection>${direction}</turningDirection>
        <timeConstantUp>${time_constant_up}</timeConstantUp>
        <timeConstantDown>${time_constant_down}</timeConstantDown>
        <maxRotVelocity>${max_rot_velocity}</maxRotVelocity>
        <motorConstant>${motor_constant}</motorConstant>
        <momentConstant>${moment_constant}</momentConstant>
        <commandSubTopic>gazebo/command/motor_speed</commandSubTopic>
        <motorNumber>${motor_number}</motorNumber>
        <rotorDragCoefficient>${rotor_drag_coefficient}</rotorDragCoefficient>
        <rollingMomentCoefficient>${rolling_moment_coefficient}</rollingMomentCoefficient>
        <motorSpeedPubTopic>motor_speed/${prefix}</motorSpeedPubTopic>
        <rotorVelocitySlowdownSim>${rotor_velocity_slowdown_sim}</rotorVelocitySlowdownSim>
      </plugin>
    </gazebo>
    <!-- -->
    <gazebo reference="${prefix}_rotor">
      <material>Gazebo/${color}</material>
    </gazebo>
    
    </xacro:macro>

 </robot>
 
 <!--XACRO DO IMU : joint , link , sensor 
  
  <xacro:macro name="imu_sensor" params="xyz rpy parent">
     
    <link name="imu_sensor_link">
        <collision>
            <origin xyz="0 0 0" rpy="0 0 0"/>
            <geometry>
                <box size="0.02 0.02 0.01"/>
            </geometry>
        </collision>
        <visual>
            <geometry>
                <box size="0.02 0.02 0.01"/>
            </geometry>
            <origin xyz="0 0 0" rpy="0 0 0"/>
             <material name="blue"/>
        </visual>
        <inertial>
            <mass value="0.001" />
            <origin xyz="0 0 0" rpy="0 0 0"/>
            <inertia ixx="0.00000015" ixy="0" ixz="0" iyy="0.00000015" iyz="0" izz="0.00000015" />
        </inertial>
    </link>
    
    <joint name="imu_sensor_joint" type="fixed">
        <axis xyz="0 0 1" />
        <origin xyz="${xyz}" rpy="${rpy}"/>
        <parent link="${parent}"/>
        <child link="imu_sensor_link"/>
    </joint>
    
    <gazebo>
        <plugin name='imu_plugin' filename='libgazebo_ros_imu.so'>
              <always_on>1</always_on>
              <topicName>imu_data</topicName>
              <bodyName>imu_sensor_link</bodyName>
              <updateRateHZ>10.0</updateRateHZ>
              <gaussianNoise>0.0</gaussianNoise>
              <xyzOffset>0 0 0</xyzOffset>
              <rpyOffset>0 0 0</rpyOffset>
        </plugin>
    </gazebo>

  </xacro:macro>
  
   -->
     <!-- CRIACAO DOS IMU  
  
   <xacro:imu_sensor xyz="0 0.05 0" rpy="0 0 0" parent="base_link" />
   -->